Workbook

Sheet Summary
A1: Windows 11 25H2 Security Baseline
A2: Settings reference and tracking workbook
A4: Baseline | B4: Security Baseline for Windows (version 25H2)
A5: Intune template ID | B5: 66df8dce-0166-4b82-92f7-1f74e3ca17a3_5
A6: Platform / channel | B6: Windows 10 and later (MDM)
A7: Configured settings | B7: =COUNTIF('Baseline Settings'!D2:D487,"Setting") -> 327
A8: Sub-settings | B8: =COUNTIF('Baseline Settings'!D2:D487,"Sub-setting") -> 159
A9: Total rows | B9: =COUNTA('Baseline Settings'!B2:B487) -> 486
A10: Categories | B10: 58
A12: Settings by category | B12: Settings | C12: Incl. sub-settings
A13: App Runtime | B13: =COUNTIFS('Baseline Settings'!B2:B487,A13,'Baseline Settings'!D2:D487,"Setting") -> 1 | C13: =COUNTIF('Baseline Settings'!B2:B487,A13) -> 1
A14: Application Management | B14: =COUNTIFS('Baseline Settings'!B2:B487,A14,'Baseline Settings'!D2:D487,"Setting") -> 3 | C14: =COUNTIF('Baseline Settings'!B2:B487,A14) -> 3
A15: Audit Settings | B15: =COUNTIFS('Baseline Settings'!B2:B487,A15,'Baseline Settings'!D2:D487,"Setting") -> 1 | C15: =COUNTIF('Baseline Settings'!B2:B487,A15) -> 1
A16: Auditing | B16: =COUNTIFS('Baseline Settings'!B2:B487,A16,'Baseline Settings'!D2:D487,"Setting") -> 23 | C16: =COUNTIF('Baseline Settings'!B2:B487,A16) -> 23
A17: AutoPlay | B17: =COUNTIFS('Baseline Settings'!B2:B487,A17,'Baseline Settings'!D2:D487,"Setting") -> 3 | C17: =COUNTIF('Baseline Settings'!B2:B487,A17) -> 5
A18: BitLocker | B18: =COUNTIFS('Baseline Settings'!B2:B487,A18,'Baseline Settings'!D2:D487,"Setting") -> 2 | C18: =COUNTIF('Baseline Settings'!B2:B487,A18) -> 3
A19: Browser (SmartScreen) | B19: =COUNTIFS('Baseline Settings'!B2:B487,A19,'Baseline Settings'!D2:D487,"Setting") -> 5 | C19: =COUNTIF('Baseline Settings'!B2:B487,A19) -> 5
A20: Connectivity | B20: =COUNTIFS('Baseline Settings'!B2:B487,A20,'Baseline Settings'!D2:D487,"Setting") -> 3 | C20: =COUNTIF('Baseline Settings'!B2:B487,A20) -> 8
A21: Credentials Delegation | B21: =COUNTIFS('Baseline Settings'!B2:B487,A21,'Baseline Settings'!D2:D487,"Setting") -> 1 | C21: =COUNTIF('Baseline Settings'!B2:B487,A21) -> 1
A22: Credentials UI | B22: =COUNTIFS('Baseline Settings'!B2:B487,A22,'Baseline Settings'!D2:D487,"Setting") -> 1 | C22: =COUNTIF('Baseline Settings'!B2:B487,A22) -> 1
A23: CredSSP | B23: =COUNTIFS('Baseline Settings'!B2:B487,A23,'Baseline Settings'!D2:D487,"Setting") -> 1 | C23: =COUNTIF('Baseline Settings'!B2:B487,A23) -> 2
A24: Data Protection | B24: =COUNTIFS('Baseline Settings'!B2:B487,A24,'Baseline Settings'!D2:D487,"Setting") -> 1 | C24: =COUNTIF('Baseline Settings'!B2:B487,A24) -> 1
A25: Device Guard | B25: =COUNTIFS('Baseline Settings'!B2:B487,A25,'Baseline Settings'!D2:D487,"Setting") -> 5 | C25: =COUNTIF('Baseline Settings'!B2:B487,A25) -> 5
A26: Device Installation | B26: =COUNTIFS('Baseline Settings'!B2:B487,A26,'Baseline Settings'!D2:D487,"Setting") -> 1 | C26: =COUNTIF('Baseline Settings'!B2:B487,A26) -> 3
A27: Device Lock | B27: =COUNTIFS('Baseline Settings'!B2:B487,A27,'Baseline Settings'!D2:D487,"Setting") -> 3 | C27: =COUNTIF('Baseline Settings'!B2:B487,A27) -> 5
A28: DMA Guard | B28: =COUNTIFS('Baseline Settings'!B2:B487,A28,'Baseline Settings'!D2:D487,"Setting") -> 1 | C28: =COUNTIF('Baseline Settings'!B2:B487,A28) -> 1
A29: DNS Client | B29: =COUNTIFS('Baseline Settings'!B2:B487,A29,'Baseline Settings'!D2:D487,"Setting") -> 1 | C29: =COUNTIF('Baseline Settings'!B2:B487,A29) -> 1
A30: Enhanced Phishing Protection | B30: =COUNTIFS('Baseline Settings'!B2:B487,A30,'Baseline Settings'!D2:D487,"Setting") -> 4 | C30: =COUNTIF('Baseline Settings'!B2:B487,A30) -> 4
A31: Event Log Service | B31: =COUNTIFS('Baseline Settings'!B2:B487,A31,'Baseline Settings'!D2:D487,"Setting") -> 3 | C31: =COUNTIF('Baseline Settings'!B2:B487,A31) -> 6
A32: Experience | B32: =COUNTIFS('Baseline Settings'!B2:B487,A32,'Baseline Settings'!D2:D487,"Setting") -> 1 | C32: =COUNTIF('Baseline Settings'!B2:B487,A32) -> 3
A33: File Explorer | B33: =COUNTIFS('Baseline Settings'!B2:B487,A33,'Baseline Settings'!D2:D487,"Setting") -> 3 | C33: =COUNTIF('Baseline Settings'!B2:B487,A33) -> 4
A34: Firewall | B34: =COUNTIFS('Baseline Settings'!B2:B487,A34,'Baseline Settings'!D2:D487,"Setting") -> 3 | C34: =COUNTIF('Baseline Settings'!B2:B487,A34) -> 23
A35: Group Policy | B35: =COUNTIFS('Baseline Settings'!B2:B487,A35,'Baseline Settings'!D2:D487,"Setting") -> 1 | C35: =COUNTIF('Baseline Settings'!B2:B487,A35) -> 3
A36: Internet Explorer | B36: =COUNTIFS('Baseline Settings'!B2:B487,A36,'Baseline Settings'!D2:D487,"Setting") -> 118 | C36: =COUNTIF('Baseline Settings'!B2:B487,A36) -> 206
A37: Kerberos | B37: =COUNTIFS('Baseline Settings'!B2:B487,A37,'Baseline Settings'!D2:D487,"Setting") -> 1 | C37: =COUNTIF('Baseline Settings'!B2:B487,A37) -> 5
A38: Lanman Server | B38: =COUNTIFS('Baseline Settings'!B2:B487,A38,'Baseline Settings'!D2:D487,"Setting") -> 8 | C38: =COUNTIF('Baseline Settings'!B2:B487,A38) -> 8
A39: Lanman Workstation | B39: =COUNTIFS('Baseline Settings'!B2:B487,A39,'Baseline Settings'!D2:D487,"Setting") -> 8 | C39: =COUNTIF('Baseline Settings'!B2:B487,A39) -> 8
A40: LAPS | B40: =COUNTIFS('Baseline Settings'!B2:B487,A40,'Baseline Settings'!D2:D487,"Setting") -> 1 | C40: =COUNTIF('Baseline Settings'!B2:B487,A40) -> 1
A41: Local Policies Security Options | B41: =COUNTIFS('Baseline Settings'!B2:B487,A41,'Baseline Settings'!D2:D487,"Setting") -> 21 | C41: =COUNTIF('Baseline Settings'!B2:B487,A41) -> 21
A42: Local Security Authority | B42: =COUNTIFS('Baseline Settings'!B2:B487,A42,'Baseline Settings'!D2:D487,"Setting") -> 2 | C42: =COUNTIF('Baseline Settings'!B2:B487,A42) -> 2
...

Sheet Baseline Settings
A1: # | B1: Category | C1: Setting | D1: Type | E1: Baseline Default | F1: Scope | G1: Description | H1: More Info
A2: 1 | B2: App Runtime | C2: Allow Microsoft accounts to be optional | D2: Setting | E2: Enabled | F2: Device | G2: This policy setting lets you control whether Microsoft accounts are optional for packaged Microsoft Store apps that require an account to sign in. This policy only affects packaged Microsoft Store apps that support it. If you enable this policy setting, packaged Microsoft Store apps that typically require a Microsoft account to sign in will allow users to sign in with an enterprise account instead. If you disable or do not configure this policy setting, users will need to sign in with a Microsoft account. | H2: Learn more
A3: 2 | B3: Application Management | C3: Allow Game DVR | D3: Setting | E3: Block | F3: Device | G3: Note The policy is only enforced in Windows 10 for desktop. Specifies whether DVR and broadcasting is allowed. Most restricted value is 0. | H3: Learn more
A4: 3 | B4: Application Management | C4: MSI Allow User Control Over Install | D4: Setting | E4: Disabled | F4: Device | G4: This policy setting permits users to change installation options that typically are available only to system administrators. If you enable this policy setting, some of the security features of Windows Installer are bypassed. It permits installations to complete that otherwise would be halted due to a security violation. If you disable or do not configure this policy setting, the security features of Windows Installer prevent users from changing installation options typically reserved for system administrators, such as specifying the directory to which files are installed. If Windows Installer detects that an installation package has permitted the user to change a protected option, it stops the installation and displays a message. These security features operate only when the installation program is running in a privileged security context in which it has access to directories denied to the user. This policy setting is designed for less restrictive environments. It can be used to circumvent errors in an installation program that prevents software from being installed. | H4: Learn more
A5: 4 | B5: Application Management | C5: MSI Always Install With Elevated Privileges | D5: Setting | E5: Disabled | F5: Device | G5: This policy setting directs Windows Installer to use elevated permissions when it installs any program on the system. If you enable this policy setting, privileges are extended to all programs. These privileges are usually reserved for programs that have been assigned to the user (offered on the desktop), assigned to the computer (installed automatically), or made available in Add or Remove Programs in Control Panel. This profile setting lets users install programs that require access to directories that the user might not have permission to view or change, including directories on highly restricted computers. If you disable or do not configure this policy setting, the system applies the current user's permissions when it installs programs that a system administrator does not distribute or offer. Note: This policy setting appears both in the Computer Configuration and User Configuration folders. To make this policy setting effective, you must enable it in both folders. Caution: Skilled users can take advantage of the permissions this policy setting grants to change their privileges and gain permanent access to restricted files and folders. Note that the User Configuration version of this policy setting is not guaranteed to be secure. | H5: Learn more
A6: 5 | B6: Audit Settings | C6: Include command line in process creation events | D6: Setting | E6: Enabled | F6: Device | G6: This policy setting determines what information is logged in security audit events when a new process has been created. This setting only applies when the Audit Process Creation policy is enabled. If you enable this policy setting the command line information for every process will be logged in plain text in the security event log as part of the Audit Process Creation event 4688, "a new process has been created," on the workstations and servers on which this policy setting is applied. If you disable or do not configure this policy setting, the process's command line information will not be included in Audit Process Creation events. Default: Not configured Note: When this policy setting is enabled, any user with access to read the security events will be able to read the command line arguments for any successfully created process. Command line arguments can contain sensitive or private information such as passwords or user data. | H6: Learn more
A7: 6 | B7: Auditing | C7: Account Logon Audit Credential Validation | D7: Setting | E7: Success+ Failure | F7: Device | G7: This policy setting allows you to audit events generated by validation tests on user account logon credentials. Events in this subcategory occur only on the computer that is authoritative for those credentials. For domain accounts, the domain controller is authoritative. For local accounts, the local computer is authoritative. | H7: Learn more
A8: 7 | B8: Auditing | C8: Account Logon Logoff Audit Account Lockout | D8: Setting | E8: Failure | F8: Device | G8: This policy setting allows you to audit events generated by a failed attempt to log on to an account that is locked out. If you configure this policy setting, an audit event is generated when an account cannot log on to a computer because the account is locked out. Success audits record successful attempts and Failure audits record unsuccessful attempts. Logon events are essential for understanding user activity and to detect potential attacks. | H8: Learn more
A9: 8 | B9: Auditing | C9: Account Logon Logoff Audit Group Membership | D9: Setting | E9: Success | F9: Device | G9: This policy allows you to audit the group memberhsip information in the user's logon token. Events in this subcategory are generated on the computer on which a logon session is created. For an interactive logon, the security audit event is generated on the computer that the user logged on to. For a network logon, such as accessing a shared folder on the network, the security audit event is generated on the computer hosting the resource. When this setting is configured, one or more security audit events are generated for each successful logon. You must also enable the Audit Logon setting under Advanced Audit Policy Configuration\System Audit Policies\Logon/Logoff. Multiple events are generated if the group memberhsip information cannot fit in a single security audit event. | H9: Learn more
A10: 9 | B10: Auditing | C10: Account Logon Logoff Audit Logon | D10: Setting | E10: Success+ Failure | F10: Device | G10: This policy setting allows you to audit events generated by user account logon attempts on the computer. Events in this subcategory are related to the creation of logon sessions and occur on the computer which was accessed. For an interactive logon, the security audit event is generated on the computer that the user account logged on to. For a network logon, such as accessing a shared folder on the network, the security audit event is generated on the computer hosting the resource. The following events are included: Successful logon attempts. Failed logon attempts. Logon attempts using explicit credentials. This event is generated when a process attempts to log on an account by explicitly specifying that account’s credentials. This most commonly occurs in batch logon configurations, such as scheduled tasks or when using the RUNAS command. Security identifiers (SIDs) were filtered and not allowed to log on. | H10: Learn more
A11: 10 | B11: Auditing | C11: Audit Authentication Policy Change | D11: Setting | E11: Success | F11: Device | G11: This policy setting allows you to audit events generated by changes to the authentication policy such as the following: Creation of forest and domain trusts. Modification of forest and domain trusts. Removal of forest and domain trusts. Changes to Kerberos policy under Computer Configuration\Windows Settings\Security Settings\Account Policies\Kerberos Policy. Granting of any of the following user rights to a user or group: Access This Computer From the Network. Allow Logon Locally. Allow Logon Through Terminal Services. Logon as a Batch Job. Logon a Service. Namespace collision. For example, when a new trust has the same name as an existing namespace name. If you configure this policy setting, an audit event is generated when an attempt to change the authentication policy is made. Success audits record successful attempts and Failure audits record unsuccessful attempts. If you do not configure this policy setting, no audit event is generated when the authentication policy is changed. Note: The security audit event is logged when the group policy is applied. It does not occur at the time when the settings are modified. | H11: Learn more
A12: 11 | B12: Auditing | C12: Audit Changes to Audit Policy | D12: Setting | E12: Success | F12: Device | G12: This policy setting allows you to audit changes in the security audit policy settings such as the following: Settings permissions and audit settings on the Audit Policy object. Changes to the system audit policy. Registration of security event sources. De-registration of security event sources. Changes to the per-user audit settings. Changes to the value of CrashOnAuditFail. Changes to the system access control list on a file system or registry object. Changes to the Special Groups list. Note: System access control list (SACL) change auditing is done when a SACL for an object changes and the policy change category is enabled. Discretionary access control list (DACL) and ownership changes are audited when object access auditing is enabled and the object's SACL is configured for auditing of DACL/Owner change. | H12: Learn more
A13: 12 | B13: Auditing | C13: Audit File Share Access | D13: Setting | E13: Success+Failure | F13: Device | G13: This policy setting allows you to audit attempts to access a shared folder. If you configure this policy setting, an audit event is generated when an attempt is made to access a shared folder. If this policy setting is defined, the administrator can specify whether to audit only successes, only failures, or both successes and failures. Note: There are no system access control lists (SACLs) for shared folders. If this policy setting is enabled, access to all shared folders on the system is audited. | H13: Learn more
... A31: 30 | B31: AutoPlay | C31: Set the default behavior for AutoRun | D31: Setting | E31: Enabled | F31: Device | G31: This policy setting sets the default behavior for Autorun commands. Autorun commands are generally stored in autorun.inf files. They often launch the installation program or other routines. Prior to Windows Vista, when media containing an autorun command is inserted, the system will automatically execute the program without user intervention. This creates a major security concern as code may be executed without user's knowledge. The default behavior starting with Windows Vista is to prompt the user whether autorun command is to be run. The autorun command is represented as a handler in the Autoplay dialog. If you enable this policy setting, an Administrator can change the default Windows Vista or later behavior for autorun to: a) Completely disable autorun commands, or b) Revert back to pre-Windows Vista behavior of automatically executing the autorun command. If you disable or not configure this policy setting, Windows Vista or later will prompt the user whether autorun command is to be run. | H31: Learn more
A32: 30.1 | B32: AutoPlay | C32: ↳ Default AutoRun Behavior | D32: Sub-setting | E32: Do not execute any autorun commands | F32: Device
A33: 31 | B33: AutoPlay | C33: Turn off Autoplay | D33: Setting | E33: Enabled | F33: Device | G33: This policy setting allows you to turn off the Autoplay feature. Autoplay begins reading from a drive as soon as you insert media in the drive. As a result, the setup file of programs and the music on audio media start immediately. Prior to Windows XP SP2, Autoplay is disabled by default on removable drives, such as the floppy disk drive (but not the CD-ROM drive), and on network drives. Starting with Windows XP SP2, Autoplay is enabled for removable drives as well, including Zip drives and some USB mass storage devices. If you enable this policy setting, Autoplay is disabled on CD-ROM and removable media drives, or disabled on all drives. This policy setting disables Autoplay on additional types of drives. You cannot use this setting to enable Autoplay on drives on which it is disabled by default. If you disable or do not configure this policy setting, AutoPlay is enabled. Note: This policy setting appears in both the Computer Configuration and User Configuration folders. If the policy settings conflict, the policy setting in Computer Configuration takes precedence over the policy setting in User Configuration. | H33: Learn more
A34: 31.1 | B34: AutoPlay | C34: ↳ Turn off Autoplay on: | D34: Sub-setting | E34: All drives | F34: Device
A35: 32 | B35: BitLocker | C35: Deny write access to fixed drives not protected by BitLocker | D35: Setting | E35: Disabled | F35: Device | G35: This policy setting determines whether BitLocker protection is required for fixed data drives to be writable on a computer. If you enable this policy setting, all fixed data drives that are not BitLocker-protected will be mounted as read-only. If the drive is protected by BitLocker, it will be mounted with read and write access. If you disable or do not configure this policy setting, all fixed data drives on the computer will be mounted with read and write access. | H35: Learn more
A36: 33 | B36: BitLocker | C36: Deny write access to removable drives not protected by BitLocker | D36: Setting | E36: Enabled | F36: Device | G36: This policy setting configures whether BitLocker protection is required for a computer to be able to write data to a removable data drive. If you enable this policy setting, all removable data drives that are not BitLocker-protected will be mounted as read-only. If the drive is protected by BitLocker, it will be mounted with read and write access. If the "Deny write access to devices configured in another organization" option is selected, only drives with identification fields matching the computer's identification fields will be given write access. When a removable data drive is accessed it will be checked for valid identification field and allowed identification fields. These fields are defined by the "Provide the unique identifiers for your organization" policy setting. If you disable or do not configure this policy setting, all removable data drives on the computer will be mounted with read and write access. Note: This policy setting can be overridden by the policy settings under User Configuration\Administrative Templates\System\Removable Storage Access. If the "Removable Disks: Deny write access" policy setting is enabled this policy setting will be ignored. | H36: Learn more
A37: 33.1 | B37: BitLocker | C37: ↳ Do not allow write access to devices configured in another organization | D37: Sub-setting | E37: False | F37: Device | H37: Learn more
A38: 34 | B38: Browser (SmartScreen) | C38: Allow Password Manager | D38: Setting | E38: Block | F38: Device | G38: This setting lets you decide whether employees can save their passwords locally, using Password Manager. | H38: Learn more
A39: 35 | B39: Browser (SmartScreen) | C39: Allow Smart Screen | D39: Setting | E39: Allow | F39: Device | G39: This setting lets you decide whether to turn on Windows Defender SmartScreen. | H39: Learn more
A40: 36 | B40: Browser (SmartScreen) | C40: Prevent Cert Error Overrides | D40: Setting | E40: Enabled | F40: Device | G40: Web security certificates are used to ensure a site your users go to is legitimate, and in some circumstances encrypts the data. With this policy, you can specify whether to prevent users from bypassing the security warning to sites that have SSL errors. If enabled, overriding certificate errors are not allowed. If disabled or not configured, overriding certificate errors are allowed. | H40: Learn more
A41: 37 | B41: Browser (SmartScreen) | C41: Prevent Smart Screen Prompt Override | D41: Setting | E41: Enabled | F41: Device | G41: Don't allow Windows Defender SmartScreen warning overrides | H41: Learn more
A42: 38 | B42: Browser (SmartScreen) | C42: Prevent Smart Screen Prompt Override For Files | D42: Setting | E42: Enabled | F42: Device | G42: Don't allow Windows Defender SmartScreen warning overrides for unverified files. | H42: Learn more
A43: 39 | B43: Connectivity | C43: Hardened UNC Paths | D43: Setting | E43: Enabled | F43: Device | G43: This policy setting configures secure access to UNC paths. If you enable this policy, Windows only allows access to the specified UNC paths after fulfilling additional security requirements. | H43: Learn more
A44: 39.1 | B44: Connectivity | C44: ↳ Hardened UNC Paths: (Device) | D44: Sub-setting | E44: Configured (4 sub-settings) | F44: Device
A45: 39.1.1 | B45: Connectivity | C45: ↳ Name | D45: Sub-setting | E45: \\*\SYSVOL | F45: Device
A46: 39.1.2 | B46: Connectivity | C46: ↳ Value | D46: Sub-setting | E46: RequireMutualAuthentication=1,RequireIntegrity=1 | F46: Device
A47: 39.1.3 | B47: Connectivity | C47: ↳ Name | D47: Sub-setting | E47: \\*\NETLOGON | F47: Device
A48: 39.1.4 | B48: Connectivity | C48: ↳ Value | D48: Sub-setting | E48: RequireMutualAuthentication=1,RequireIntegrity=1 | F48: Device
A49: 40 | B49: Connectivity | C49: Turn off downloading of print drivers over HTTP | D49: Setting | E49: Enabled | F49: Device | G49: This policy setting specifies whether to allow this client to download print driver packages over HTTP. To set up HTTP printing, non-inbox drivers need to be downloaded over HTTP. Note: This policy setting does not prevent the client from printing to printers on the Intranet or the Internet over HTTP. It only prohibits downloading drivers that are not already installed locally. If you enable this policy setting, print drivers cannot be downloaded over HTTP. If you disable or do not configure this policy setting, users can download print drivers over HTTP. | H49: Learn more
A50: 41 | B50: Connectivity | C50: Turn off Internet download for Web publishing and online ordering wizards | D50: Setting | E50: Enabled | F50: Device | G50: This policy setting specifies whether Windows should download a list of providers for the web publishing and online ordering wizards. These wizards allow users to select from a list of companies that provide services such as online storage and photographic printing. By default, Windows displays providers downloaded from a Windows website in addition to providers specified in the registry. If you enable this policy setting, Windows does not download providers, and only the service providers that are cached in the local registry are displayed. If you disable or do not configure this policy setting, a list of providers are downloaded when the user uses the web publishing or online ordering wizards. See the documentation for the web publishing and online ordering wizards for more information, including details on specifying service providers in the registry. | H50: Learn more
A51: 42 | B51: Credentials Delegation | C51: Remote host allows delegation of non-exportable credentials | D51: Setting | E51: Enabled | F51: Device | G51: Remote host allows delegation of non-exportable credentials When using credential delegation, devices provide an exportable version of credentials to the remote host. This exposes users to the risk of credential theft from attackers on the remote host. If you enable this policy setting, the host supports Restricted Admin or Remote Credential Guard mode. If you disable or do not configure this policy setting, Restricted Administration and Remote Credential Guard mode are not supported. User will always need to pass their credentials to the host. | H51: Learn more
A52: 43 | B52: Credentials UI | C52: Enumerate administrator accounts on elevation | D52: Setting | E52: Disabled | F52: Device | G52: This policy setting controls whether administrator accounts are displayed when a user attempts to elevate a running application. By default, administrator accounts are not displayed when the user attempts to elevate a running application. If you enable this policy setting, all local administrator accounts on the PC will be displayed so the user can choose one and enter the correct password. If you disable this policy setting, users will always be required to type a user name and password to elevate. | H52: Learn more
A53: 44 | B53: CredSSP | C53: Encryption Oracle Remediation | D53: Setting | E53: Enabled | F53: Device | G53: Encryption Oracle Remediation This policy setting applies to applications using the CredSSP component (for example: Remote Desktop Connection). Some versions of the CredSSP protocol are vulnerable to an encryption oracle attack against the client. This policy controls compatibility with vulnerable clients and servers. This policy allows you to set the level of protection desired for the encryption oracle vulnerability. If you enable this policy setting, CredSSP version support will be selected based on the following options: Force Updated Clients: Client applications which use CredSSP will not be able to fall back to the insecure versions and services using CredSSP will not accept unpatched clients. Note: this setting should not be deployed until all remote hosts support the newest version. Mitigated: Client applications which use CredSSP will not be able to fall back to the insecure version but services using CredSSP will accept unpatched clients. See the link below for important information about the risk posed by remaining unpatched clients. Vulnerable: Client applications which use CredSSP will expose the remote servers to attacks by supporting fall back to the insecure versions and services using CredSSP will accept unpatched clients. For more information about the vulnerability and servicing requirements for protection, see https://go.microsoft.com/fwlink/?linkid=866660 | H53: Learn more
A54: 44.1 | B54: CredSSP | C54: ↳ Protection Level: (Device) | D54: Sub-setting | E54: Force Updated Clients | F54: Device
A55: 45 | B55: Data Protection | C55: Allow Direct Memory Access | D55: Setting | E55: Block | F55: Device | G55: This policy setting allows you to block direct memory access (DMA) for all hot pluggable PCI downstream ports until a user logs into Windows. Once a user logs in, Windows will enumerate the PCI devices connected to the host plug PCI ports. Every time the user locks the machine, DMA will be blocked on hot plug PCI ports with no children devices until the user logs in again. Devices which were already enumerated when the machine was unlocked will continue to function until unplugged. This policy setting is only enforced when BitLocker Device Encryption is enabled. Most restricted value is 0. | H55: Learn more
A56: 46 | B56: Device Guard | C56: Configure System Guard Launch | D56: Setting | E56: Unmanaged Enables Secure Launch if supported by hardware | F56: Device | G56: Secure Launch configuration: 0 - Unmanaged, configurable by Administrative user, 1 - Enables Secure Launch if supported by hardware, 2 - Disables Secure Launch. | H56: Learn more
A57: 47 | B57: Device Guard | C57: Credential Guard | D57: Setting | E57: (Enabled with UEFI lock) Turns on Credential Guard with UEFI lock. | F57: Device | G57: Credential Guard Configuration: 0 - Turns off CredentialGuard remotely if configured previously without UEFI Lock, 1 - Turns on CredentialGuard with UEFI lock. 2 - Turns on CredentialGuard without UEFI lock. | H57: Learn more
...

Sheet Administrative Templates
A1: # | B1: Category | C1: Setting | D1: Type | E1: Baseline Default | F1: Scope | G1: Description | H1: More Info
A2: 1 | B2: App Runtime | C2: Allow Microsoft accounts to be optional | D2: Setting | E2: Enabled | F2: Device | G2: This policy setting lets you control whether Microsoft accounts are optional for packaged Microsoft Store apps that require an account to sign in. This policy only affects packaged Microsoft Store apps that support it. If you enable this policy setting, packaged Microsoft Store apps that typically require a Microsoft account to sign in will allow users to sign in with an enterprise account instead. If you disable or do not configure this policy setting, users will need to sign in with a Microsoft account. | H2: Learn more
A3: 2 | B3: Application Management | C3: Allow Game DVR | D3: Setting | E3: Block | F3: Device | G3: Note The policy is only enforced in Windows 10 for desktop. Specifies whether DVR and broadcasting is allowed. Most restricted value is 0. | H3: Learn more
A4: 3 | B4: Application Management | C4: MSI Allow User Control Over Install | D4: Setting | E4: Disabled | F4: Device | G4: This policy setting permits users to change installation options that typically are available only to system administrators. If you enable this policy setting, some of the security features of Windows Installer are bypassed. It permits installations to complete that otherwise would be halted due to a security violation. If you disable or do not configure this policy setting, the security features of Windows Installer prevent users from changing installation options typically reserved for system administrators, such as specifying the directory to which files are installed. If Windows Installer detects that an installation package has permitted the user to change a protected option, it stops the installation and displays a message. These security features operate only when the installation program is running in a privileged security context in which it has access to directories denied to the user. This policy setting is designed for less restrictive environments. It can be used to circumvent errors in an installation program that prevents software from being installed. | H4: Learn more
A5: 4 | B5: Application Management | C5: MSI Always Install With Elevated Privileges | D5: Setting | E5: Disabled | F5: Device | G5: This policy setting directs Windows Installer to use elevated permissions when it installs any program on the system. If you enable this policy setting, privileges are extended to all programs. These privileges are usually reserved for programs that have been assigned to the user (offered on the desktop), assigned to the computer (installed automatically), or made available in Add or Remove Programs in Control Panel. This profile setting lets users install programs that require access to directories that the user might not have permission to view or change, including directories on highly restricted computers. If you disable or do not configure this policy setting, the system applies the current user's permissions when it installs programs that a system administrator does not distribute or offer. Note: This policy setting appears both in the Computer Configuration and User Configuration folders. To make this policy setting effective, you must enable it in both folders. Caution: Skilled users can take advantage of the permissions this policy setting grants to change their privileges and gain permanent access to restricted files and folders. Note that the User Configuration version of this policy setting is not guaranteed to be secure. | H5: Learn more
A6: 5 | B6: Audit Settings | C6: Include command line in process creation events | D6: Setting | E6: Enabled | F6: Device | G6: This policy setting determines what information is logged in security audit events when a new process has been created. This setting only applies when the Audit Process Creation policy is enabled. If you enable this policy setting the command line information for every process will be logged in plain text in the security event log as part of the Audit Process Creation event 4688, "a new process has been created," on the workstations and servers on which this policy setting is applied. If you disable or do not configure this policy setting, the process's command line information will not be included in Audit Process Creation events. Default: Not configured Note: When this policy setting is enabled, any user with access to read the security events will be able to read the command line arguments for any successfully created process. Command line arguments can contain sensitive or private information such as passwords or user data. | H6: Learn more
A7: 29 | B7: AutoPlay | C7: Disallow Autoplay for non-volume devices | D7: Setting | E7: Enabled | F7: Device | G7: This policy setting disallows AutoPlay for MTP devices like cameras or phones. If you enable this policy setting, AutoPlay is not allowed for MTP devices like cameras or phones. If you disable or do not configure this policy setting, AutoPlay is enabled for non-volume devices. | H7: Learn more
A8: 30 | B8: AutoPlay | C8: Set the default behavior for AutoRun | D8: Setting | E8: Enabled | F8: Device | G8: This policy setting sets the default behavior for Autorun commands. Autorun commands are generally stored in autorun.inf files. They often launch the installation program or other routines. Prior to Windows Vista, when media containing an autorun command is inserted, the system will automatically execute the program without user intervention. This creates a major security concern as code may be executed without user's knowledge. The default behavior starting with Windows Vista is to prompt the user whether autorun command is to be run. The autorun command is represented as a handler in the Autoplay dialog. If you enable this policy setting, an Administrator can change the default Windows Vista or later behavior for autorun to: a) Completely disable autorun commands, or b) Revert back to pre-Windows Vista behavior of automatically executing the autorun command. If you disable or not configure this policy setting, Windows Vista or later will prompt the user whether autorun command is to be run. | H8: Learn more
A9: 30.1 | B9: AutoPlay | C9: ↳ Default AutoRun Behavior | D9: Sub-setting | E9: Do not execute any autorun commands | F9: Device
A10: 31 | B10: AutoPlay | C10: Turn off Autoplay | D10: Setting | E10: Enabled | F10: Device | G10: This policy setting allows you to turn off the Autoplay feature. Autoplay begins reading from a drive as soon as you insert media in the drive. As a result, the setup file of programs and the music on audio media start immediately. Prior to Windows XP SP2, Autoplay is disabled by default on removable drives, such as the floppy disk drive (but not the CD-ROM drive), and on network drives. Starting with Windows XP SP2, Autoplay is enabled for removable drives as well, including Zip drives and some USB mass storage devices. If you enable this policy setting, Autoplay is disabled on CD-ROM and removable media drives, or disabled on all drives. This policy setting disables Autoplay on additional types of drives. You cannot use this setting to enable Autoplay on drives on which it is disabled by default. If you disable or do not configure this policy setting, AutoPlay is enabled. Note: This policy setting appears in both the Computer Configuration and User Configuration folders. If the policy settings conflict, the policy setting in Computer Configuration takes precedence over the policy setting in User Configuration. | H10: Learn more
A11: 31.1 | B11: AutoPlay | C11: ↳ Turn off Autoplay on: | D11: Sub-setting | E11: All drives | F11: Device
A12: 32 | B12: BitLocker | C12: Deny write access to fixed drives not protected by BitLocker | D12: Setting | E12: Disabled | F12: Device | G12: This policy setting determines whether BitLocker protection is required for fixed data drives to be writable on a computer. If you enable this policy setting, all fixed data drives that are not BitLocker-protected will be mounted as read-only. If the drive is protected by BitLocker, it will be mounted with read and write access. If you disable or do not configure this policy setting, all fixed data drives on the computer will be mounted with read and write access. | H12: Learn more
A13: 33 | B13: BitLocker | C13: Deny write access to removable drives not protected by BitLocker | D13: Setting | E13: Enabled | F13: Device | G13: This policy setting configures whether BitLocker protection is required for a computer to be able to write data to a removable data drive. If you enable this policy setting, all removable data drives that are not BitLocker-protected will be mounted as read-only. If the drive is protected by BitLocker, it will be mounted with read and write access. If the "Deny write access to devices configured in another organization" option is selected, only drives with identification fields matching the computer's identification fields will be given write access. When a removable data drive is accessed it will be checked for valid identification field and allowed identification fields. These fields are defined by the "Provide the unique identifiers for your organization" policy setting. If you disable or do not configure this policy setting, all removable data drives on the computer will be mounted with read and write access. Note: This policy setting can be overridden by the policy settings under User Configuration\Administrative Templates\System\Removable Storage Access. If the "Removable Disks: Deny write access" policy setting is enabled this policy setting will be ignored. | H13: Learn more
A14: 33.1 | B14: BitLocker | C14: ↳ Do not allow write access to devices configured in another organization | D14: Sub-setting | E14: False | F14: Device | H14: Learn more
A15: 42 | B15: Credentials Delegation | C15: Remote host allows delegation of non-exportable credentials | D15: Setting | E15: Enabled | F15: Device | G15: Remote host allows delegation of non-exportable credentials When using credential delegation, devices provide an exportable version of credentials to the remote host. This exposes users to the risk of credential theft from attackers on the remote host. If you enable this policy setting, the host supports Restricted Admin or Remote Credential Guard mode. If you disable or do not configure this policy setting, Restricted Administration and Remote Credential Guard mode are not supported. User will always need to pass their credentials to the host. | H15: Learn more
A16: 43 | B16: Credentials UI | C16: Enumerate administrator accounts on elevation | D16: Setting | E16: Disabled | F16: Device | G16: This policy setting controls whether administrator accounts are displayed when a user attempts to elevate a running application. By default, administrator accounts are not displayed when the user attempts to elevate a running application. If you enable this policy setting, all local administrator accounts on the PC will be displayed so the user can choose one and enter the correct password. If you disable this policy setting, users will always be required to type a user name and password to elevate. | H16: Learn more
A17: 44 | B17: CredSSP | C17: Encryption Oracle Remediation | D17: Setting | E17: Enabled | F17: Device | G17: Encryption Oracle Remediation This policy setting applies to applications using the CredSSP component (for example: Remote Desktop Connection). Some versions of the CredSSP protocol are vulnerable to an encryption oracle attack against the client. This policy controls compatibility with vulnerable clients and servers. This policy allows you to set the level of protection desired for the encryption oracle vulnerability. If you enable this policy setting, CredSSP version support will be selected based on the following options: Force Updated Clients: Client applications which use CredSSP will not be able to fall back to the insecure versions and services using CredSSP will not accept unpatched clients. Note: this setting should not be deployed until all remote hosts support the newest version. Mitigated: Client applications which use CredSSP will not be able to fall back to the insecure version but services using CredSSP will accept unpatched clients. See the link below for important information about the risk posed by remaining unpatched clients. Vulnerable: Client applications which use CredSSP will expose the remote servers to attacks by supporting fall back to the insecure versions and services using CredSSP will accept unpatched clients. For more information about the vulnerability and servicing requirements for protection, see https://go.microsoft.com/fwlink/?linkid=866660 | H17: Learn more
A18: 44.1 | B18: CredSSP | C18: ↳ Protection Level: (Device) | D18: Sub-setting | E18: Force Updated Clients | F18: Device
A19: 51 | B19: Device Installation | C19: Prevent installation of devices using drivers that match these device setup classes | D19: Setting | E19: Enabled | F19: Device | G19: This policy setting allows you to specify a list of device setup class globally unique identifiers (GUIDs) for device drivers that Windows is prevented from installing. This policy setting takes precedence over any other policy setting that allows Windows to install a device. If you enable this policy setting, Windows is prevented from installing or updating device drivers whose device setup class GUIDs appear in the list you create. If you enable this policy setting on a remote desktop server, the policy setting affects redirection of the specified devices from a remote desktop client to the remote desktop server. If you disable or do not configure this policy setting, Windows can install and update devices as allowed or prevented by other policy settings. | H19: Learn more
A20: 51.1 | B20: Device Installation | C20: ↳ Also apply to matching devices that are already installed. | D20: Sub-setting | E20: True | F20: Device | H20: Learn more
A21: 51.2 | B21: Device Installation | C21: ↳ Prevented Classes | D21: Sub-setting | E21: {d48179be-ec20-11d1-b6b8-00c04fa372a7} | F21: Device | H21: Learn more
A22: 56 | B22: DNS Client | C22: Turn off multicast name resolution | D22: Setting | E22: Enabled | F22: Device | G22: Specifies that link local multicast name resolution (LLMNR) is disabled on client computers. LLMNR is a secondary name resolution protocol. With LLMNR, queries are sent using multicast over a local network link on a single subnet from a client computer to another client computer on the same subnet that also has LLMNR enabled. LLMNR does not require a DNS server or DNS client configuration, and provides name resolution in scenarios in which conventional DNS name resolution is not possible. If you enable this policy setting, LLMNR will be disabled on all available network adapters on the client computer. If you disable this policy setting, or you do not configure this policy setting, LLMNR will be enabled on all available network adapters. | H22: Learn more
A23: 61 | B23: Event Log Service | C23: Specify the maximum log file size (KB) | D23: Setting | E23: Enabled | F23: Device | G23: This policy setting specifies the maximum size of the log file in kilobytes. If you enable this policy setting, you can configure the maximum log file size to be between 1 megabyte (1024 kilobytes) and 2 terabytes (2147483647 kilobytes), in kilobyte increments. If you disable or do not configure this policy setting, the maximum size of the log file will be set to the locally configured value. This value can be changed by the local administrator using the Log Properties dialog, and it defaults to 1 megabyte. | H23: Learn more
A24: 61.1 | B24: Event Log Service | C24: ↳ Maximum Log Size (KB) | D24: Sub-setting | E24: 32768 | F24: Device
A25: 62 | B25: Event Log Service | C25: Specify the maximum log file size (KB) | D25: Setting | E25: Enabled | F25: Device | G25: This policy setting specifies the maximum size of the log file in kilobytes. If you enable this policy setting, you can configure the maximum log file size to be between 20 megabytes (20480 kilobytes) and 2 terabytes (2147483647 kilobytes), in kilobyte increments. If you disable or do not configure this policy setting, the maximum size of the log file will be set to the locally configured value. This value can be changed by the local administrator using the Log Properties dialog, and it defaults to 20 megabytes. | H25: Learn more
A26: 62.1 | B26: Event Log Service | C26: ↳ Maximum Log Size (KB) | D26: Sub-setting | E26: 196608 | F26: Device
A27: 63 | B27: Event Log Service | C27: Specify the maximum log file size (KB) | D27: Setting | E27: Enabled | F27: Device | G27: This policy setting specifies the maximum size of the log file in kilobytes. If you enable this policy setting, you can configure the maximum log file size to be between 1 megabyte (1024 kilobytes) and 2 terabytes (2147483647 kilobytes), in kilobyte increments. If you disable or do not configure this policy setting, the maximum size of the log file will be set to the locally configured value. This value can be changed by the local administrator using the Log Properties dialog, and it defaults to 1 megabyte. | H27: Learn more
A28: 63.1 | B28: Event Log Service | C28: ↳ Maximum Log Size (KB) | D28: Sub-setting | E28: 32768 | F28: Device
A29: 64 | B29: Experience | C29: Allow Windows Spotlight (User) | D29: Setting | E29: Allow | F29: User | G29: Specifies whether to turn off all Windows spotlight features at once. If you enable this policy setting, Windows spotlight on lock screen, Windows Tips, Microsoft consumer features and other related features will be turned off. You should enable this policy setting if your goal is to minimize network traffic from target devices. If you disable or do not configure this policy setting, Windows spotlight features are allowed and may be controlled individually using their corresponding policy settings. Most restricted value is 0. | H29: Learn more
A30: 64.1 | B30: Experience | C30: ↳ Allow Third Party Suggestions In Windows Spotlight (User) | D30: Sub-setting | E30: Block | F30: User | G30: Specifies whether to allow app and content suggestions from third-party software publishers in Windows spotlight features like lock screen spotlight, suggested apps in the Start menu, and Windows tips. Users may still see suggestions for Microsoft features, apps, and services. | H30: Learn more
A31: 64.2 | B31: Experience | C31: ↳ Allow Windows Consumer Features | D31: Sub-setting | E31: Block | F31: Device | G31: This policy allows IT admins to turn on experiences that are typically for consumers only, such as Start suggestions, Membership notifications, Post-OOBE app install and redirect tiles. | H31: Learn more
A32: 65 | B32: File Explorer | C32: Configure Windows Defender SmartScreen | D32: Setting | E32: Enabled | F32: Device | G32: This policy allows you to turn Windows Defender SmartScreen on or off. SmartScreen helps protect PCs by warning users before running potentially malicious programs downloaded from the Internet. This warning is presented as an interstitial dialog shown before running an app that has been downloaded from the Internet and is unrecognized or known to be malicious. No dialog is shown for apps that do not appear to be suspicious. Some information is sent to Microsoft about files and programs run on PCs with this feature enabled. If you enable this policy, SmartScreen will be turned on for all users. Its behavior can be controlled by the following options: • Warn and prevent bypass • Warn If you enable this policy with the "Warn and prevent bypass" option, SmartScreen's dialogs will not present the user with the option to disregard the warning and run the app. SmartScreen will continue to show the warning on subsequent attempts to run the app. If you enable this policy with the "Warn" option, SmartScreen's dialogs will warn the user that the app appears suspicious, but will permit the user to disregard the warning and run the app anyway. SmartScreen will not warn the user again for that app if the user tells SmartScreen to run the app. If you disable this policy, SmartScreen will be turned off for all users. Users will not be warned if they try to run suspicious apps from the Internet. If you do not configure this policy, SmartScreen will be enabled by default, but users may change their settings. | H32: Learn more
A33: 65.1 | B33: File Explorer | C33: ↳ Pick one of the following settings: (Device) | D33: Sub-setting | E33: Warn and prevent bypass | F33: Device
A34: 66 | B34: File Explorer | C34: Turn off Data Execution Prevention for Explorer | D34: Setting | E34: Disabled | F34: Device | G34: Disabling data execution prevention can allow certain legacy plug-in applications to function without terminating Explorer. | H34: Learn more
A35: 67 | B35: File Explorer | C35: Turn off heap termination on corruption | D35: Setting | E35: Disabled | F35: Device | G35: Disabling heap termination on corruption can allow certain legacy plug-in applications to function without terminating Explorer immediately, although Explorer may still terminate unexpectedly later. | H35: Learn more
A36: 71 | B36: Group Policy | C36: Configure registry policy processing | D36: Setting | E36: Enabled | F36: Device | G36: This policy setting determines when registry policies are updated. This policy setting affects all policies in the Administrative Templates folder and any other policies that store values in the registry. It overrides customized settings that the program implementing a registry policy set when it was installed. If you enable this policy setting, you can use the check boxes provided to change the options. If you disable or do not configure this policy setting, it has no effect on the system. The "Do not apply during periodic background processing" option prevents the system from updating affected policies in the background while the computer is in use. When background updates are disabled, policy changes will not take effect until the next user logon or system restart. The "Process even if the Group Policy objects have not changed" option updates and reapplies the policies even if the policies have not changed. Many policy implementations specify that they are updated only when changed. However, you might want to update unchanged policies, such as reapplying a desired policy setting in case a user has changed it. | H36: Learn more
A37: 71.1 | B37: Group Policy | C37: ↳ Do not apply during periodic background processing (Device) | D37: Sub-setting | E37: False | F37: Device
A38: 71.2 | B38: Group Policy | C38: ↳ Process even if the Group Policy objects have not changed (Device) | D38: Sub-setting | E38: True | F38: Device
A39: 72 | B39: Internet Explorer | C39: Access data sources across domains | D39: Setting | E39: Enabled | F39: Device | G39: This policy setting allows you to manage whether Internet Explorer can access data from another security zone using the Microsoft XML Parser (MSXML) or ActiveX Data Objects (ADO). If you enable this policy setting, users can load a page in the zone that uses MSXML or ADO to access data from another site in the zone. If you select Prompt in the drop-down box, users are queried to choose whether to allow a page to be loaded in the zone that uses MSXML or ADO to access data from another site in the zone. If you disable this policy setting, users cannot load a page in the zone that uses MSXML or ADO to access data from another site in the zone. If you do not configure this policy setting, users cannot load a page in the zone that uses MSXML or ADO to access data from another site in the zone. | H39: Learn more
A40: 72.1 | B40: Internet Explorer | C40: ↳ Access data sources across domains | D40: Sub-setting | E40: Disable | F40: Device
...
